Workbook

Sheet Summary
A1: LAPORAN KINERJA KLAIM NON KENDARAAN BERMOTOR PT. ASURANSI CENTRAL ASIA CABANG SURABAYA 1 (per 19 Juli 2018)
A54: 1.1 Klaim Tahun 2010 sampai dengan Tahun 2018
A55: Gambar 1.1 merupakan persentase setiap LOB terhadap jumlah keseluruhan klaim non kendaraan bermotor PT. Asuransi Central Asia cabang Surabaya 1 tahun 2010 hingga tahun 2018.
A76: Gambar 1.1. Persentase LOB Terhadap Jumlah Klaim Non Kendaraan Bermotor PT. Asuransi Central Asia cabang Surabaya 1 Th. 2010 s/d 2018
A79: Gambar 1.2 merupakan perbandingan persentase LOB terhadap jumlah keseluruhan klaim dengan status outstanding tahun 2010 hingga tahun 2018.
A99: Gambar 1.2. Persentase LOB Terhadap Jumlah Klaim Non Kendaraan Bermotor dengan Status Outstanding PT. Asuransi Central Asia cabang Surabaya 1 Th. 2010 s/d 2018
A110: Gambar 1.3 merupakan jumlah klaim non kendaraan bermotor PT. Asuransi Central Asia cabang Surabaya 1 berdasarkan LOB dan tahun dari tahun 2010 hingga Tahun 2018.
A129: Tahun | B129: 2010 | C129: =B129+1 -> 2011 | D129: =C129+1 -> 2012 | E129: =D129+1 -> 2013 | F129: =E129+1 -> 2014 | G129: =F129+1 -> 2015 | H129: =G129+1 -> 2016 | I129: =H129+1 -> 2017 | J129: =I129+1 -> 2018
A130: Jumlah Klaim* | B130: =Calculate!C25 -> 195 | C130: =Calculate!D25 -> 145 | D130: =Calculate!E25 -> 163 | E130: =Calculate!F25 -> 215 | F130: =Calculate!G25 -> 189 | G130: =Calculate!H25 -> 239 | H130: =Calculate!I25 -> 324 | I130: =Calculate!J25 -> 215 | J130: =Calculate!K25 -> 61
A131: *dalam unit
A132: Gambar 1.3. Jumlah Klaim Non Kendaraan Bermotor Berdasarkan LOB dan Tahun PT. Asuransi Central Asia cabang Surabaya 1 Th. 2010 s/d 2018
A135: Gambar 1.4 merupakan jumlah klaim non kendaraan bermotor PT. Asuransi Central Asia cabang Surabaya 1 berdasarkan status klaim dan tahun dari tahun 2010 hingga Tahun 2018.
A149: Tahun | B149: 2010 | C149: =B149+1 -> 2011 | D149: =C149+1 -> 2012 | E149: =D149+1 -> 2013 | F149: =E149+1 -> 2014 | G149: =F149+1 -> 2015 | H149: =G149+1 -> 2016 | I149: =H149+1 -> 2017 | J149: =I149+1 -> 2018
A150: Settled*, ** | B150: =Calculate!V32 -> 193 | C150: =Calculate!W32 -> 138 | D150: =Calculate!X32 -> 152 | E150: =Calculate!Y32 -> 209 | F150: =Calculate!Z32 -> 187 | G150: =Calculate!AA32 -> 195 | H150: =Calculate!AB32 -> 255 | I150: =Calculate!AC32 -> 159 | J150: =Calculate!AD32 -> 13
A151: Outstanding*, *** | B151: =Calculate!V33 -> 2 | C151: =Calculate!W33 -> 7 | D151: =Calculate!X33 -> 11 | E151: =Calculate!Y33 -> 6 | F151: =Calculate!Z33 -> 2 | G151: =Calculate!AA33 -> 44 | H151: =Calculate!AB33 -> 69 | I151: =Calculate!AC33 -> 56 | J151: =Calculate!AD33 -> 48
A152: Persentase settled **** | B152: =B150/SUM(B150:B151) -> 0.98974359 | C152: =IFERROR(C150/SUM(C150:C151),0) -> 0.95172414 | D152: =IFERROR(D150/SUM(D150:D151),0) -> 0.93251534 | E152: =IFERROR(E150/SUM(E150:E151),0) -> 0.97209302 | F152: =IFERROR(F150/SUM(F150:F151),0) -> 0.98941799 | G152: =IFERROR(G150/SUM(G150:G151),0) -> 0.81589958 | H152: =IFERROR(H150/SUM(H150:H151),0) -> 0.78703704 | I152: =IFERROR(I150/SUM(I150:I151),0) -> 0.73953488 | J152: =IFERROR(J150/SUM(J150:J151),0) -> 0.21311475
A153: *jumlah klaim dalam unit | E153: *** Jumlah Settled | H153: =SUM(Calculate!C25:R25)-SUM(Calculate!C36:R36) -> 1501 | I153: Klaim
A154: ***jumlah Outstanding | C154: =SUM(Calculate!C36:R36) -> 245 | D154: Klaim | E154: **** Persentase Settled | H154: =H153/SUM(H153,C154) -> 0.85967927
A155: Gambar 1.4. Jumlah Klaim Non Kendaraan Bermotor Berdasarkan Status Klaim dan Tahun PT. Asuransi Central Asia cabang Surabaya 1 Th. 2010 s/d 2018
A158: Gambar 1.5 merupakan jumlah klaim dengan status outstanding non kendaraan bermotor PT. Asuransi Central Asia cabang Surabaya 1 berdasarkan LOB dan tahun dari tahun 2010 hingga tahun 2018.
A180: Gambar 1.5. Jumlah Klaim Outstanding Non Kendaraan Bermotor Berdasarkan LOB dan Tahun PT. Asuransi Central Asia cabang Surabaya 1 Th. 2010 s/d 2018
A183: 1.2 Kinerja Klaim Non Kendaraan Bermotor PT. Asuransi Central Asia cabang Surabaya 1
A184: Gambar 1.6 merupakan perbandingan jumlah settled klaim berdasarakan LOB pada tahun 2016, 2017, dan 2018 klaim non kendaraan bermotor PT. Asuransi Central Asia cabang Surabaya 1
A204: ="Tahun "&RIGHT(Calculate!D39,4) -> Tahun 2017 | B204: =SUM(Calculate!$D$40:$D$45) -> 313 | C204: klaim | D204: ="Tahun "&RIGHT(Calculate!E39,4)&"*,**" -> Tahun 2018*,** | F204: =SUM(Calculate!$E$40:$E$45) -> 67 | G204: klaim
A205: *progres dari 2017 ke 2018 | E205: =F204/B204 -> 0.21405751 | F205: ** Jumlah belum 1 tahun penuh
A206: *peningkatan dari 2016 *** ke 2017 | E206: =(B204-I206)/I206 -> 0.33191489 | F206: *** Jumlah settled tahun 2016 | I206: =SUM(Calculate!C40:C45) -> 235 | J206: klaim
A207: Gambar 1.6. Perbandingan Jumlah Settled Klaim Non Kendaraan Bermotor Berdasarkan LOB PT. Asuransi Central Asia cabang Surabaya 1 Tahun 2016, 2017, dan 2018
A211: 1.3 Klaim Dalam Pantauan
A212: Gambar 1.7 merupakan jumlah klaim yang masih dalam pantauan divisi klaim non kendaraan bermotor PT. Asuransi Central Asia cabang Surabaya 1
A233: Tahun | B233: 2010 | C233: =B233+1 -> 2011 | D233: =C233+1 -> 2012 | E233: =D233+1 -> 2013 | F233: =E233+1 -> 2014 | G233: =F233+1 -> 2015 | H233: =G233+1 -> 2016 | I233: =H233+1 -> 2017 | J233: =I233+1 -> 2018
A234: Jumlah Klaim*,** | B234: =Calculate!C73 -> 2 | C234: =Calculate!D73 -> 10 | D234: =Calculate!E73 -> 14 | E234: =Calculate!F73 -> 8 | F234: =Calculate!G73 -> 1 | G234: =Calculate!H73 -> 45 | H234: =Calculate!I73 -> 73 | I234: =Calculate!J73 -> 60 | J234: =Calculate!K73 -> 51
A235: *dalam unit
A236: ** Jumlah klaim seluruhnya | C236: =SUM(Calculate!C73:R73) -> 264 | D236: Klaim
A237: Gambar 1.7. Jumlah Klaim Non Kendaraan Bermotor yang Dipantaun Berdasarkan LOB dan Tahun PT. Asuransi Central Asia cabang Surabaya 1 Th. 2010 s/d 2018
A240: Gambar 1.8 merupakan persentase klaim yang dipantau berdasarakan periode waktu update klaim non kendaraan bermotor PT. Asuransi Central Asia cabang Surabaya 1
A260: Gambar 1.8. Persentase Periode Waktu Update pada Jumlah Klaim yang Dipantau PT. Asuransi Central Asia cabang Surabaya 1
A265: Dari gambar 1.8 secara detail klaim dengan periode update lebih dari 30 hari, dapat dilihat pada gambar 1.9 berdasarkan LOB.
A286: Gambar 1.9. Jumlah Klaim Berdasarkan LOB pada Periode Waktu Update Lebih dari 30 Hari

Sheet Fire
A1: Fire
A50: 2.1. Klaim Settled dan Outstanding
A51: Adapun perbandingan klaim Fire dengan status settled dan outstanding di PT. Asuransi Central Asia cabang Surabaya 1, dijelaskan pada gambar berikut ini.
A69: Tahun | B69: 2010 | C69: =B69+1 -> 2011 | D69: =C69+1 -> 2012 | E69: =D69+1 -> 2013 | F69: =E69+1 -> 2014 | G69: =F69+1 -> 2015 | H69: =G69+1 -> 2016 | I69: =H69+1 -> 2017 | J69: =I69+1 -> 2018
A70: Jumlah Klaim* | B70: =SUM(Calculate!C2:C3) -> 136 | C70: =SUM(Calculate!D2:D3) -> 80 | D70: =SUM(Calculate!E2:E3) -> 107 | E70: =SUM(Calculate!F2:F3) -> 118 | F70: =SUM(Calculate!G2:G3) -> 107 | G70: =SUM(Calculate!H2:H3) -> 100 | H70: =SUM(Calculate!I2:I3) -> 168 | I70: =SUM(Calculate!J2:J3) -> 134 | J70: =SUM(Calculate!K2:K3) -> 35
A71: *dalam unit | B71: **Jumlah Outstanding | D71: =Calculate!S3 -> 93 | E71: Klaim | F71: **Jumlah Settled | H71: =Calculate!S2 -> 892 | I71: Klaim
D72: =D71/(D71+H71) -> 0.094416244 | H72: =H71/(D71+H71) -> 0.90558376
A73: Gambar 2.1 Jumlah Klaim Berdasarkan Tahun Register dan Kondisi Klaim
A75: Dari data pada gambar 2.1 rincian jenis polis dan otority penanganan klaim dijelaskan pada gambar berikut ini.
A92: Tahun | B92: 2010 | C92: =B92+1 -> 2011 | D92: =C92+1 -> 2012 | E92: =D92+1 -> 2013 | F92: =E92+1 -> 2014 | G92: =F92+1 -> 2015 | H92: =G92+1 -> 2016 | I92: =H92+1 -> 2017 | J92: =I92+1 -> 2018
A93: Polis ACA * | B93: =Calculate!AC3 -> 89 | C93: =Calculate!AC4 -> 59 | D93: =Calculate!AC5 -> 60 | E93: =Calculate!AC6 -> 74 | F93: =Calculate!AC7 -> 58 | G93: =Calculate!AC8 -> 42 | H93: =Calculate!AC9 -> 52 | I93: =Calculate!AC10 -> 41 | J93: =Calculate!AC11 -> 17
B94: =IFERROR(B93/(B93+B95),0) -> 0.65441176 | C94: =IFERROR(C93/(C93+C95),0) -> 0.7375 | D94: =IFERROR(D93/(D93+D95),0) -> 0.56074766 | E94: =IFERROR(E93/(E93+E95),0) -> 0.62711864 | F94: =IFERROR(F93/(F93+F95),0) -> 0.54205607 | G94: =IFERROR(G93/(G93+G95),0) -> 0.42 | H94: =IFERROR(H93/(H93+H95),0) -> 0.30952381 | I94: =IFERROR(I93/(I93+I95),0) -> 0.30597015 | J94: =IFERROR(J93/(J93+J95),0) -> 0.48571429
A95: Polis Inward* | B95: =Calculate!AD3 -> 47 | C95: =Calculate!AD4 -> 21 | D95: =Calculate!AD5 -> 47 | E95: =Calculate!AD6 -> 44 | F95: =Calculate!AD7 -> 49 | G95: =Calculate!AD8 -> 58 | H95: =Calculate!AD9 -> 116 | I95: =Calculate!AD10 -> 93 | J95: =Calculate!AD11 -> 18
B96: =IFERROR(B95/(B93+B95),0) -> 0.34558824 | C96: =IFERROR(C95/(C93+C95),0) -> 0.2625 | D96: =IFERROR(D95/(D93+D95),0) -> 0.43925234 | E96: =IFERROR(E95/(E93+E95),0) -> 0.37288136 | F96: =IFERROR(F95/(F93+F95),0) -> 0.45794393 | G96: =IFERROR(G95/(G93+G95),0) -> 0.58 | H96: =IFERROR(H95/(H93+H95),0) -> 0.69047619 | I96: =IFERROR(I95/(I93+I95),0) -> 0.69402985 | J96: =IFERROR(J95/(J93+J95),0) -> 0.51428571
A97: *jumlah polis dalam unit
A98: Gambar 2.2 Jumlah Klaim Berdasarkan Tahun Register, Jenis Polis, dan Otority
A100: 2.2. Perbandingan Jumlah Klaim Berdasarkan Date of Loss dan Jumlah Settled pada Tahun 2016, 2017, dan 2018
A102: Jumlah kejadian dengan kategori klaim Fire yang masuk pada PT. Asuransi Central Asia cabang Surabaya 1 bervariasi setiap bulan, berikut ini gambar grafik jumlah klaim berdasarkan waktu kejadian.
A122: Gambar 2.3 Perbandingan Jumlah Klaim Berdasarkan Date of Loss pada Tahun 2016, 2017, dan 2018 setiap Bulan dan Akumulasi
A125: Salah satu pengukuran kinerja dari divisi klaim adalah jumlah klaim yang berhail diselesaikan (settled), gambar 2.4 merupakan perbandingan jumlah klaim Fire dengan status settled dalam bulan berjalan dari tahun sebelumnya pada divisi klaim non kendaraan bermotor PT. Asuransi Central Asia cabang Surabaya 1.
A146: Gambar 2.4 Perbandingan Komulatif Klaim dapat Dilakukan Settled Klaim pada Tahun 2016, 2017, dan 2018 Setiap Bulan
A150: 2.3. Klaim dalam Pantauan
A151: Adapun jumlah klaim Fire dalam pantauan dari tahun 2010 hingga 2018 di PT. Asuransi Central Asia cabang Surabaya 1, dijelaskan pada gambar berikut ini.
A168: Tahun | B168: 2010 | C168: =B168+1 -> 2011 | D168: =C168+1 -> 2012 | E168: =D168+1 -> 2013 | F168: =E168+1 -> 2014 | G168: =F168+1 -> 2015 | H168: =G168+1 -> 2016 | I168: =H168+1 -> 2017 | J168: =I168+1 -> 2018
A169: Jumlah Klaim*,** | B169: =Calculate!C67 -> 1 | C169: =Calculate!D67 -> 1 | D169: =Calculate!E67 -> 5 | E169: =Calculate!F67 -> 4 | F169: =Calculate!G67 -> 1 | G169: =Calculate!H67 -> 2 | H169: =Calculate!I67 -> 19 | I169: =Calculate!J67 -> 37 | J169: =Calculate!K67 -> 32
A170: *dalam unit | B170: **Total | D170: =SUM(Calculate!C67:R67) -> 102 | E170: Klaim
A171: Gambar 2.5. Jumlah Klaim yang Dipantau Berdasarkan Tahun Register
A173: Dalam proses memantau klaim Fire di PT. Asuransi Central Asia cabang Surabaya 1 dibagi menjadi 4 (empat) kategori berdasarkan lama update klaim yaitu kurang dari sampai 7 hari, antara 7 sampai 14 hari, antara 14 sampai 30 hari, dan lebih dari 30 hari, adapun rincian tersebut dijelaskan pada gambar 2.6.
A194: Tahun | B194: 2010 | C194: =B194+1 -> 2011 | D194: =C194+1 -> 2012 | E194: =D194+1 -> 2013 | F194: =E194+1 -> 2014 | G194: =F194+1 -> 2015 | H194: =G194+1 -> 2016 | I194: =H194+1 -> 2017 | J194: =I194+1 -> 2018
A195: Lama Update > 30 hari* | B195: =Calculate!C86 -> 0 | C195: =Calculate!D86 -> 0 | D195: =Calculate!E86 -> 0 | E195: =Calculate!F86 -> 0 | F195: =Calculate!G86 -> 0 | G195: =Calculate!H86 -> 0 | H195: =Calculate!I86 -> 0 | I195: =Calculate!J86 -> 0 | J195: =Calculate!K86 -> 2
A197: *Jumlah Klaim dalam unit
A198: Gambar 2.6. Jumlah Klaim yang Dipantau Berdasarkan Tahun Register
A200: Dari data gambar 2.6 secara akumalasi berdasarkan kategori, dijelaskan pada gambar berikut ini.
A218: Gambar 2.8. Jumlah Klaim yang Dipantau Berdasarkan Lama Waktu Update

Sheet Fire1
A1: Dari gambar 2.7 terdapat beberapa klaim bermasalah. adapun data klaim dan kendala dijabarkan pada tabel 2.1. berikut ini.
A3: Tabel 2.1. Data Klaim Fire yang Bermasalah
A4: No. | B4: No. Klaim | C4: Nama Tertanggung | D4: Alasan | E4: Tanggal Update | F4: Status Update | G4: Solusi ditawarkan
A5: 1 | B5: 01.31.17.000091 | C5: Angkasa Pura I ( Juanda-Surabaya) | D5: Leader terlambat lapor DOL 05,08,2011 dan dilaporkan tahun 2017 | E5: 05,07,18 | F5: reminder 2 minta bukti pemberitahuan awal ke Bp. Siswanto JASINDO 20,04,18 reminder 2 Bpk Edo minta bnatuna ACA HO
A6: 2 | B6: 01.31.16.000156 | C6: Sakari Sumber Abadi | D6: TTG tidak setuju atas penawaran yang diberikan olah ACA | E6: 06,07,18 | F6: Bpk Hendro email ke Ibu Masrianan dan usulkan adjustment cabang
A7: 4 | B7: 01.31.14.000100 | C7: Deverindo Indograha Raya and/or ascott international management indonesia and/or somerset surabaya | D7: tanggal 19.06.17 Permintaan Pak Surya disuruh biarkan
A8: 5 | B8: 01.31.13.000048 | C8: Deverindo Indograha Raya | D8: tanggal 19.06.17 Permintaan Pak Surya disuruh biarkan
A9: 6 | B9: 01.31.10.000077 | C9: Juliati Boddhiya | D9: Dokumen Hard Copy Tidak Ada
A10: 7 | B10: 01.31.12.000096 | C10: Gudang Garam | D10: Dokumen klaim belum komplit. info leader tidak mempunyai data dokumen klaim ini karena klaim sudah lama (klaim tidak ditagihkan lagi oleh leader) | E10: 30,05,18 | F10: reminder 3 14,03,18 Bpk Hendro minta arahan ke HO 20,02,18 reminder Bapak Edo minta saran Bpk Herna dan Ibu Nana HO
A11: 8 | B11: 01.31.12.000097 | C11: Gudang Garam
A12: 9 | B12: 01.31.12.000098 | C12: Gudang Garam
A13: 10 | B13: 01.31.13.000036 | C13: Surya Zig Zag
A14: 11 | B14: 01.31.13.000058 | C14: Surya Pemenang
A15: 12 | B15: 01.31.14.000044 | C15: Gudang Garam
A16: 13 | B16: 01.31.18.000006 | C16: Bank Maspion qq Guinco Kota Mas | D16: klaim berpotensi under deductible, | E16: 07,06,18 | F16: belum diputuskan klaim ditolak atau tidak
A17: 14 | B17: 83101021805000001 | C17: Geraja Pantekosta Pusat Surabaya | D17: klaim ditolak, menunggu TTG memutuskan ajukan ex-gratia atau tidal | E17: 08,06,18

Sheet Cargo
A1: Cargo
A51: 3.1. Klaim Settled dan Outstanding
A52: Adapun perbandingan klaim Cargo dengan status settled dan outstanding di PT. Asuransi Central Asia cabang Surabaya 1, dijelaskan pada gambar berikut ini.
A70: Tahun | B70: 2010 | C70: =B70+1 -> 2011 | D70: =C70+1 -> 2012 | E70: =D70+1 -> 2013 | F70: =E70+1 -> 2014 | G70: =F70+1 -> 2015 | H70: =G70+1 -> 2016 | I70: =H70+1 -> 2017 | J70: =I70+1 -> 2018
A71: Jumlah Klaim* | B71: =SUM(Calculate!C4:C5) -> 33 | C71: =SUM(Calculate!D4:D5) -> 33 | D71: =SUM(Calculate!E4:E5) -> 36 | E71: =SUM(Calculate!F4:F5) -> 52 | F71: =SUM(Calculate!G4:G5) -> 48 | G71: =SUM(Calculate!H4:H5) -> 35 | H71: =SUM(Calculate!I4:I5) -> 37 | I71: =SUM(Calculate!J4:J5) -> 20 | J71: =SUM(Calculate!K4:K5) -> 11
A72: *dalam unit | B72: **Jumlah Outstanding | D72: =Calculate!S5 -> 27 | E72: Klaim | F72: **Jumlah Settled | H72: =Calculate!S4 -> 278 | I72: Klaim
D73: =D72/(D72+H72) -> 0.08852459 | H73: =H72/(D72+H72) -> 0.91147541
A74: Gambar 3.1 Jumlah Klaim Berdasarkan Tahun Register dan Kondisi Klaim
A76: Dari data pada gambar 3.1 rincian jenis polis dan otority penanganan klaim dijelaskan pada gambar berikut ini.
A94: Tahun | B94: 2010 | C94: =B94+1 -> 2011 | D94: =C94+1 -> 2012 | E94: =D94+1 -> 2013 | F94: =E94+1 -> 2014 | G94: =F94+1 -> 2015 | H94: =G94+1 -> 2016 | I94: =H94+1 -> 2017 | J94: =I94+1 -> 2018
A95: Polis ACA * | B95: =Calculate!AL3 -> 14 | C95: =Calculate!AL4 -> 19 | D95: =Calculate!AL5 -> 27 | E95: =Calculate!AL6 -> 43 | F95: =Calculate!AL7 -> 47 | G95: =Calculate!AL8 -> 31 | H95: =Calculate!AL9 -> 23 | I95: =Calculate!AL10 -> 14 | J95: =Calculate!AM11 -> 3
B96: =IFERROR(B95/(B95+B97),0) -> 0.42424242 | C96: =IFERROR(C95/(C95+C97),0) -> 0.57575758 | D96: =IFERROR(D95/(D95+D97),0) -> 0.75 | E96: =IFERROR(E95/(E95+E97),0) -> 0.82692308 | F96: =IFERROR(F95/(F95+F97),0) -> 0.97916667 | G96: =IFERROR(G95/(G95+G97),0) -> 0.88571429 | H96: =IFERROR(H95/(H95+H97),0) -> 0.62162162 | I96: =IFERROR(I95/(I95+I97),0) -> 0.7 | J96: =IFERROR(J95/(J95+J97),0) -> 1
A97: Polis Inward* | B97: =Calculate!AM3 -> 19 | C97: =Calculate!AM4 -> 14 | D97: =Calculate!AM5 -> 9 | E97: =Calculate!AM6 -> 9 | F97: =Calculate!AM7 -> 1 | G97: =Calculate!AM8 -> 4 | H97: =Calculate!AM9 -> 14 | I97: =Calculate!AM10 -> 6 | J97: =Calculate!AN11 -> 0
B98: =IFERROR(B97/(B95+B97),0) -> 0.57575758 | C98: =IFERROR(C97/(C95+C97),0) -> 0.42424242 | D98: =IFERROR(D97/(D95+D97),0) -> 0.25 | E98: =IFERROR(E97/(E95+E97),0) -> 0.17307692 | F98: =IFERROR(F97/(F95+F97),0) -> 0.020833333 | G98: =IFERROR(G97/(G95+G97),0) -> 0.11428571 | H98: =IFERROR(H97/(H95+H97),0) -> 0.37837838 | I98: =IFERROR(I97/(I95+I97),0) -> 0.3 | J98: =IFERROR(J97/(J95+J97),0) -> 0
A99: *jumlah polis dalam unit
A100: Gambar 3.2 Jumlah Klaim Berdasarkan Tahun Register, Jenis Polis, dan Otority
A101: 3.2. Perbandingan Jumlah Klaim Berdasarkan Date of Loss dan Jumlah Settled pada Tahun 2016, 2017, dan 2018
A103: Jumlah kejadian dengan kategori klaim cargo yang masuk pada PT. Asuransi Central Asia cabang Surabaya 1 bervariasi setiap bulan, berikut ini gambar grafik jumlah klaim berdasarkan waktu kejadian.
A123: Gambar 3.3 Perbandingan Jumlah Klaim Berdasarkan Date of Loss pada Tahun 2016, 2017, dan 2018 setiap Bulan dan Akumulasi
A126: Salah satu pengukuran kinerja dari divisi klaim adalah jumlah klaim yang berhail diselesaikan (settled), gambar 3.4 merupakan perbandingan jumlah klaim cargo dengan status settled dalam bulan berjalan dari tahun sebelumnya pada divisi klaim non kendaraan bermotor PT. Asuransi Central Asia cabang Surabaya 1.
A147: Gambar 3.4 Perbandingan Komulatif Klaim Sudah Dilakukan Settled Klaim pada Tahun 2016, 2017, dan 2018 Setiap Bulan
A151: 3.3. Klaim dalam Pantauan
A152: Adapun jumlah klaim Cargo dalam pantauan dari tahun 2010 hingga 2018 di PT.Asuransi Central Asia cabang Surabaya 1, dijelaskan pada gambar berikut ini.
A169: Tahun | B169: 2010 | C169: =B169+1 -> 2011 | D169: =C169+1 -> 2012 | E169: =D169+1 -> 2013 | F169: =E169+1 -> 2014 | G169: =F169+1 -> 2015 | H169: =G169+1 -> 2016 | I169: =H169+1 -> 2017 | J169: =I169+1 -> 2018
A170: Jumlah Klaim*,** | B170: =Calculate!C68 -> 0 | C170: =Calculate!D68 -> 5 | D170: =Calculate!E68 -> 5 | E170: =Calculate!F68 -> 1 | F170: =Calculate!G68 -> 0 | G170: =Calculate!H68 -> 0 | H170: =Calculate!I68 -> 5 | I170: =Calculate!J68 -> 2 | J170: =Calculate!K68 -> 10
A171: *dalam unit | B171: **Total | D171: =SUM(Calculate!C68:R68) -> 28 | E171: Klaim
A172: Gambar 3.5. Jumlah Klaim yang Dipantau Berdasarkan Tahun Register
A174: Dalam proses memantau klaim Cargo di PT. Asuransi Central Asia cabang Surabaya 1 dibagi menjadi 4 (empat) kategori berdasarkan lama update klaim yaitu kurang dari sampai 7 hari, antara 7 sampai 14 hari, antara 14 sampai 30 hari, dan lebih dari 30 hari, adapun rincian tersebut dijelaskan pada gambar 3.6.
A195: Tahun | B195: 2010 | C195: =B195+1 -> 2011 | D195: =C195+1 -> 2012 | E195: =D195+1 -> 2013 | F195: =E195+1 -> 2014 | G195: =F195+1 -> 2015 | H195: =G195+1 -> 2016 | I195: =H195+1 -> 2017 | J195: =I195+1 -> 2018
A196: Lama Update > 30 hari* | B196: =Calculate!C87 -> 0 | C196: =Calculate!D87 -> 0 | D196: =Calculate!E87 -> 0 | E196: =Calculate!F87 -> 0 | F196: =Calculate!G87 -> 0 | G196: =Calculate!H87 -> 0 | H196: =Calculate!I87 -> 0 | I196: =Calculate!J87 -> 0 | J196: =Calculate!K87 -> 0
A198: *Jumlah Klaim dalam unit
A199: Gambar 3.6. Jumlah Klaim yang Dipantau Berdasarkan Tahun Register
A201: Dari data gambar 3.6 secara akumalasi berdasarkan kategori, dijelaskan pada gambar berikut ini.
A219: Gambar 3.7. Jumlah Klaim yang Dipantau Berdasarkan Lama Waktu Update

Sheet Cargo1
A1: Dari gambar 3.7 terdapat beberapa klaim bermasalah. adapun data klaim dan kendala dijabarkan pada tabel 3.1. berikut ini.
A3: Tabel 3.1. Data Klaim Cargo yang Bermasalah
A4: No. | B4: No. Klaim | C4: Nama Tertanggung | D4: Alasan | E4: Tanggal Update | F4: Status Update | G4: Solusi ditawarkan
A5: 1 | B5: 11.31.16.000001 | C5: Pakerin | D5: Tertanggung tidak memberikan dokumen yang diminta adjuster | E5: 11,07,18 | F5: reminder 7 TTG 21,11,17 Bpk Hendro reminder ke TTG 11.08.17 Bpk Hendro email ke TTG minta tanggapan permintaan dokumen ,25.07.17 ajukan kembali penolakan dokumen ke KACAB, 17,05,2018 Pak Surya telpon ke pak Henry
A6: 2 | B6: 11.31.11.000019 | C6: PR Tjap Gudang Garam | D6: Dokumen klaim belum komplit. info leader tidak mempunyai data dokumen klaim ini karena klaim sudah lama (klaim tidak ditagihkan lagi oleh leader) | E6: 11,07,18 | F6: reminder 5, 14,03,18 Bpk Hendro minta arahan ke HO 20,02,18 reminder Bapak Edo minta saran Bpk Herna dan Ibu Nana HO
A7: 3 | B7: 11.31.12.000012 | C7: PR Tjap Gudang Garam
A8: 4 | B8: 11.31.12.000013 | C8: Surya Zig Zag
A9: 5 | B9: 11.31.12.000016 | C9: Gudang Garam
A10: 6 | B10: 11.31.12.000017 | C10: Gudang Garam

Sheet CPM
A1: CPM
A50: 4.1. Klaim Settled dan Outstanding
A51: Adapun perbandingan klaim CPM dengan status settled dan outstanding di PT.Asuransi Central Asia cabang Surabaya 1, dijelaskan pada gambar berikut ini.
A69: Tahun | B69: 2010 | C69: =B69+1 -> 2011 | D69: =C69+1 -> 2012 | E69: =D69+1 -> 2013 | F69: =E69+1 -> 2014 | G69: =F69+1 -> 2015 | H69: =G69+1 -> 2016 | I69: =H69+1 -> 2017 | J69: =I69+1 -> 2018
A70: Jumlah Klaim* | B70: =SUM(Calculate!C8:C9) -> 0 | C70: =SUM(Calculate!D8:D9) -> 0 | D70: =SUM(Calculate!E8:E9) -> 0 | E70: =SUM(Calculate!F8:F9) -> 0 | F70: =SUM(Calculate!G8:G9) -> 1 | G70: =SUM(Calculate!H8:H9) -> 38 | H70: =SUM(Calculate!I8:I9) -> 54 | I70: =SUM(Calculate!J8:J9) -> 1 | J70: =SUM(Calculate!K8:K9) -> 0
A71: *dalam unit | B71: **Jumlah Outstanding | D71: =Calculate!S9 -> 65 | E71: Klaim | F71: **Jumlah Settled | H71: =Calculate!S8 -> 29 | I71: Klaim
D72: =D71/(D71+H71) -> 0.69148936 | H72: =H71/(D71+H71) -> 0.30851064
A73: Gambar 4.1 Jumlah Klaim Berdasarkan Tahun Register dan Kondisi Klaim
A75: Dari data pada gambar 4.1 rincian jenis polis dan otority penanganan klaim dijelaskan pada gambar berikut ini.
A93: Tahun | B93: 2010 | C93: =B93+1 -> 2011 | D93: =C93+1 -> 2012 | E93: =D93+1 -> 2013 | F93: =E93+1 -> 2014 | G93: =F93+1 -> 2015 | H93: =G93+1 -> 2016 | I93: =H93+1 -> 2017 | J93: =I93+1 -> 2018
A94: Polis ACA * | B94: =Calculate!BD3 -> 0 | C94: =Calculate!BD4 -> 0 | D94: =Calculate!BD5 -> 0 | E94: =Calculate!BD6 -> 0 | F94: =Calculate!BD7 -> 1 | G94: =Calculate!BD8 -> 4 | H94: =Calculate!BD9 -> 1 | I94: =Calculate!BD10 -> 1 | J94: =Calculate!BD11 -> 0
B95: =IFERROR(B94/(B94+B96),0) -> 0 | C95: =IFERROR(C94/(C94+C96),0) -> 0 | D95: =IFERROR(D94/(D94+D96),0) -> 0 | E95: =IFERROR(E94/(E94+E96),0) -> 0 | F95: =IFERROR(F94/(F94+F96),0) -> 1 | G95: =IFERROR(G94/(G94+G96),0) -> 0.10526316 | H95: =IFERROR(H94/(H94+H96),0) -> 0.018518519 | I95: =IFERROR(I94/(I94+I96),0) -> 1 | J95: =IFERROR(J94/(J94+J96),0) -> 0
A96: Polis Inward* | B96: =Calculate!BE3 -> 0 | C96: =Calculate!BE4 -> 0 | D96: =Calculate!BE5 -> 0 | E96: =Calculate!BE6 -> 0 | F96: =Calculate!BE7 -> 0 | G96: =Calculate!BE8 -> 34 | H96: =Calculate!BE9 -> 53 | I96: =Calculate!BE10 -> 0 | J96: =Calculate!BE11 -> 0
B97: =IFERROR(B96/(B94+B96),0) -> 0 | C97: =IFERROR(C96/(C94+C96),0) -> 0 | D97: =IFERROR(D96/(D94+D96),0) -> 0 | E97: =IFERROR(E96/(E94+E96),0) -> 0 | F97: =IFERROR(F96/(F94+F96),0) -> 0 | G97: =IFERROR(G96/(G94+G96),0) -> 0.89473684 | H97: =IFERROR(H96/(H94+H96),0) -> 0.98148148 | I97: =IFERROR(I96/(I94+I96),0) -> 0 | J97: =IFERROR(J96/(J94+J96),0) -> 0
A98: *jumlah polis dalam unit
A99: Gambar 4.2 Jumlah Klaim Berdasarkan Tahun Register, Jenis Polis, dan Otority
A100: 4.2. Perbandingan Jumlah Klaim Berdasarkan Date of Loss dan Jumlah Settled pada Tahun 2016, 2017, dan 2018
A102: Jumlah kejadian dengan kategori klaim CPM yang masuk pada PT. Asuransi Central Asia cabang Surabaya 1 bervariasi setiap bulan, berikut ini gambar grafik jumlah klaim berdasarkan waktu kejadian.
A122: Gambar 4.3 Perbandingan Jumlah Klaim Berdasarkan Date of Loss pada Tahun 2016, 2017, dan 2018 setiap Bulan dan Akumulasi
A125: Salah satu pengukuran kinerja dari divisi klaim adalah jumlah klaim yang berhail diselesaikan (settled), gambar 4.4 merupakan perbandingan jumlah klaim CPM dengan status settled dalam bulan berjalan dari tahun sebelumnya pada divisi klaim non kendaraan bermotor PT. Asuransi Central Asia cabang Surabaya 1.
A146: Gambar 4.4 Perbandingan Komulatif Klaim Sudah Dilakukan Settled Klaim pada Tahun 2016, 2017 dan 2018 Setiap Bulan
A150: 4.3. Klaim dalam Pantauan
A151: Adapun jumlah klaim CPM dalam pantauan dari tahun 2010 hingga 2018 di PT.Asuransi Central Asia cabang Surabaya 1, dijelaskan pada gambar berikut ini.
A168: Tahun | B168: 2010 | C168: =B168+1 -> 2011 | D168: =C168+1 -> 2012 | E168: =D168+1 -> 2013 | F168: =E168+1 -> 2014 | G168: =F168+1 -> 2015 | H168: =G168+1 -> 2016 | I168: =H168+1 -> 2017 | J168: =I168+1 -> 2018
A169: Jumlah Klaim*,** | B169: =Calculate!C70 -> 0 | C169: =Calculate!D70 -> 0 | D169: =Calculate!E70 -> 0 | E169: =Calculate!F70 -> 0 | F169: =Calculate!G70 -> 0 | G169: =Calculate!H70 -> 30 | H169: =Calculate!I70 -> 36 | I169: =Calculate!J70 -> 0 | J169: =Calculate!K70 -> 0
A170: *dalam unit | B170: **Total | D170: =SUM(Calculate!C70:R70) -> 66 | E170: Klaim
A171: Gambar 4.5. Jumlah Klaim yang Dipantau Berdasarkan Tahun Register
A173: Dalam proses memantau klaim CPM di PT. Asuransi Central Asia cabang Surabaya 1 dibagi menjadi 4 (empat) kategori berdasarkan lama update klaim yaitu kurang dari sampai 7 hari, antara 7 sampai 14 hari, antara 14 sampai 30 hari, dan lebih dari 30 hari, adapun rincian tersebut dijelaskan pada gambar 4.6.
A194: Tahun | B194: 2010 | C194: =B194+1 -> 2011 | D194: =C194+1 -> 2012 | E194: =D194+1 -> 2013 | F194: =E194+1 -> 2014 | G194: =F194+1 -> 2015 | H194: =G194+1 -> 2016 | I194: =H194+1 -> 2017 | J194: =I194+1 -> 2018
A195: Lama Update > 30 hari* | B195: =Calculate!C89 -> 0 | C195: =Calculate!D89 -> 0 | D195: =Calculate!E89 -> 0 | E195: =Calculate!F89 -> 0 | F195: =Calculate!G89 -> 0 | G195: =Calculate!H89 -> 0 | H195: =Calculate!I89 -> 0 | I195: =Calculate!J89 -> 0 | J195: =Calculate!K89 -> 0
A197: *Jumlah Klaim dalam unit
A198: Gambar 4.6. Jumlah Klaim yang Dipantau Berdasarkan Tahun Register
A200: Dari data gambar 4.6 secara akumalasi berdasarkan kategori, dijelaskan pada gambar berikut ini.
A218: Gambar 4.7. Jumlah Klaim yang Dipantau Berdasarkan Lama Waktu Update

Sheet CPM1
A1: Dari gambar 4.7 terdapat beberapa klaim bermasalah, adapun data klaim dan kendala dijabarkan pada tabel 4.1, berikut ini.
A3: Tabel 4.1. Data Klaim CPM yang Bermasalah
A4: No. | B4: No. Klaim | C4: Nama Tertanggung | D4: Alasan | E4: Tanggal Update | F4: Status Update | G4: Solusi ditawarkan

Sheet Hull
A1: Hull
A50: 5.1. Klaim Settled dan Outstanding
A51: Adapun perbandingan klaim Hull dengan status settled dan outstanding di PT.Asuransi Central Asia cabang Surabaya 1, dijelaskan pada gambar berikut ini.
A69: Tahun | B69: 2010 | C69: =B69+1 -> 2011 | D69: =C69+1 -> 2012 | E69: =D69+1 -> 2013 | F69: =E69+1 -> 2014 | G69: =F69+1 -> 2015 | H69: =G69+1 -> 2016 | I69: =H69+1 -> 2017 | J69: =I69+1 -> 2018
A70: Jumlah Klaim* | B70: =SUM(Calculate!C6:C7) -> 5 | C70: =SUM(Calculate!D6:D7) -> 8 | D70: =SUM(Calculate!E6:E7) -> 7 | E70: =SUM(Calculate!F6:F7) -> 1 | F70: =SUM(Calculate!G6:G7) -> 0 | G70: =SUM(Calculate!H6:H7) -> 0 | H70: =SUM(Calculate!I6:I7) -> 2 | I70: =SUM(Calculate!J6:J7) -> 4 | J70: =SUM(Calculate!K6:K7) -> 0
A71: *dalam unit | B71: **Jumlah Outstanding | D71: =Calculate!S7 -> 6 | E71: Klaim | F71: **Jumlah Settled | H71: =Calculate!S6 -> 21 | I71: Klaim
D72: =D71/(D71+H71) -> 0.22222222 | H72: =H71/(D71+H71) -> 0.77777778
A73: Gambar 5.1 Jumlah Klaim Berdasarkan Tahun Register dan Kondisi Klaim
A75: Dari data pada gambar 5.1 rincian jenis polis dan otority penanganan klaim dijelaskan pada gambar berikut ini.
A93: Tahun | B93: 2010 | C93: =B93+1 -> 2011 | D93: =C93+1 -> 2012 | E93: =D93+1 -> 2013 | F93: =E93+1 -> 2014 | G93: =F93+1 -> 2015 | H93: =G93+1 -> 2016 | I93: =H93+1 -> 2017 | J93: =I93+1 -> 2018
A94: Polis ACA * | B94: =Calculate!AU3 -> 3 | C94: =Calculate!AU4 -> 3 | D94: =Calculate!AU5 -> 3 | E94: =Calculate!AU6 -> 1 | F94: =Calculate!AU7 -> 0 | G94: =Calculate!AU8 -> 0 | H94: =Calculate!AU9 -> 2 | I94: =Calculate!AU10 -> 4 | J94: =Calculate!AU11 -> 0
B95: =IFERROR(B94/(B94+B96),0) -> 0.6 | C95: =IFERROR(C94/(C94+C96),0) -> 0.375 | D95: =IFERROR(D94/(D94+D96),0) -> 0.42857143 | E95: =IFERROR(E94/(E94+E96),0) -> 1 | F95: =IFERROR(F94/(F94+F96),0) -> 0 | G95: =IFERROR(G94/(G94+G96),0) -> 0 | H95: =IFERROR(H94/(H94+H96),0) -> 1 | I95: =IFERROR(I94/(I94+I96),0) -> 1 | J95: =IFERROR(J94/(J94+J96),0) -> 0
A96: Polis Inward* | B96: =Calculate!AV3 -> 2 | C96: =Calculate!AV4 -> 5 | D96: =Calculate!AV5 -> 4 | E96: =Calculate!AV6 -> 0 | F96: =Calculate!AV7 -> 0 | G96: =Calculate!AV8 -> 0 | H96: =Calculate!AV9 -> 0 | I96: =Calculate!AV10 -> 0 | J96: =Calculate!AV11 -> 0
B97: =IFERROR(B96/(B94+B96),0) -> 0.4 | C97: =IFERROR(C96/(C94+C96),0) -> 0.625 | D97: =IFERROR(D96/(D94+D96),0) -> 0.57142857 | E97: =IFERROR(E96/(E94+E96),0) -> 0 | F97: =IFERROR(F96/(F94+F96),0) -> 0 | G97: =IFERROR(G96/(G94+G96),0) -> 0 | H97: =IFERROR(H96/(H94+H96),0) -> 0 | I97: =IFERROR(I96/(I94+I96),0) -> 0 | J97: =IFERROR(J96/(J94+J96),0) -> 0
A98: *jumlah polis dalam unit
A99: Gambar 5.2 Jumlah Klaim Berdasarkan Tahun Register, Jenis Polis, dan Otority
A100: 5.2. Perbandingan Jumlah Klaim Berdasarkan Date of Loss dan Jumlah Settled pada Tahun 2016, 2017, dan 2018
A102: Jumlah kejadian dengan kategori klaim hull yang masuk pada PT. Asuransi Central Asia cabang Surabaya 1 bervariasi setiap bulan, berikut ini gambar grafik jumlah klaim berdasarkan waktu kejadian.
A122: Gambar 5.3 Perbandingan Jumlah Klaim Berdasarkan Date of Loss pada Tahun 2016, 2017, dan 2018 setiap Bulan dan Akumulasi
A125: Salah satu pengukuran kinerja dari divisi klaim adalah jumlah klaim yang berhail diselesaikan (settled), gambar 5.4 merupakan perbandingan jumlah klaim hull dengan status settled dalam bulan berjalan dari tahun sebelumnya pada divisi klaim non kendaraan bermotor PT. Asuransi Central Asia cabang Surabaya 1.
A146: Gambar 5.4 Perbandingan Komulatif Klaim Sudah Dilakukan Settled Klaim pada Tahun 2016, 2017, dan 2018 Setiap Bulan
A150: 5.3. Klaim dalam Pantauan
A151: Adapun jumlah klaim Hull dalam pantauan dari tahun 2010 hingga 2018 di PT.Asuransi Central Asia cabang Surabaya 1, dijelaskan pada gambar berikut ini.
A168: Tahun | B168: 2010 | C168: =B168+1 -> 2011 | D168: =C168+1 -> 2012 | E168: =D168+1 -> 2013 | F168: =E168+1 -> 2014 | G168: =F168+1 -> 2015 | H168: =G168+1 -> 2016 | I168: =H168+1 -> 2017 | J168: =I168+1 -> 2018
A169: Jumlah Klaim*,** | B169: =Calculate!C69 -> 1 | C169: =Calculate!D69 -> 2 | D169: =Calculate!E69 -> 3 | E169: =Calculate!F69 -> 0 | F169: =Calculate!G69 -> 0 | G169: =Calculate!H69 -> 0 | H169: =Calculate!I69 -> 0 | I169: =Calculate!J69 -> 3 | J169: =Calculate!K69 -> 0
A170: *dalam unit | B170: **Total | D170: =SUM(Calculate!C69:R69) -> 9 | E170: Klaim
A171: Gambar 5.5. Jumlah Klaim yang Dipantau Berdasarkan Tahun Register
A173: Dalam proses memantau klaim Hull di PT. Asuransi Central Asia cabang Surabaya 1 dibagi menjadi 4 (empat) kategori berdasarkan lama update klaim yaitu kurang dari sampai 7 hari, antara 7 sampai 14 hari, antara 14 sampai 30 hari, dan lebih dari 30 hari, adapun rincian tersebut dijelaskan pada gambar 5.6.
A194: Tahun | B194: 2010 | C194: =B194+1 -> 2011 | D194: =C194+1 -> 2012 | E194: =D194+1 -> 2013 | F194: =E194+1 -> 2014 | G194: =F194+1 -> 2015 | H194: =G194+1 -> 2016 | I194: =H194+1 -> 2017 | J194: =I194+1 -> 2018
A195: Lama Update > 30 hari* | B195: =Calculate!C88 -> 0 | C195: =Calculate!D88 -> 0 | D195: =Calculate!E88 -> 1 | E195: =Calculate!F88 -> 0 | F195: =Calculate!G88 -> 0 | G195: =Calculate!H88 -> 0 | H195: =Calculate!I88 -> 0 | I195: =Calculate!J88 -> 0 | J195: =Calculate!K88 -> 0
A197: *Jumlah Klaim dalam unit
A198: Gambar 5.6. Jumlah Klaim yang Dipantau Berdasarkan Tahun Register
A200: Dari data gambar 5.6 secara akumalasi berdasarkan kategori, dijelaskan pada gambar berikut ini.
A218: Gambar 5.7. Jumlah Klaim yang Dipantau Berdasarkan Lama Waktu Update

Sheet Hull1
A1: Dari gambar 5.7 terdapat beberapa klaim bermasalah, adapun data klaim dan kendala dijabarkan pada tabel 5.1, berikut ini.
A3: Tabel 5.1. Data Klaim Hull yang Bermasalah
A4: No. | B4: No. Klaim | C4: Nama Tertanggung | D4: Alasan | E4: Tanggal Update | F4: Status Update | G4: Solusi ditawarkan
A5: 1 | B5: 12.31.15.000007 | C5: Bank Mandiri (persero) Tbk qq Pelayaran Alkan Abadi qq Rickey Sujatno | D5: tgl. 06.07.2017 info tertanggung mengalami pailit, tgl 18.10.16 kirim penawaran ganti rugi | E5: 06.07.17 | F5: info tertanggung mengalami pailit, tgl 18.10.16 kirim penawaran ganti rugi

Sheet Casualty
A1: Casualty
A50: 6.1. Klaim Settled dan Outstanding
A51: Adapun perbandingan klaim Casualty dengan status settled dan outstanding di PT.Asuransi Central Asia cabang Surabaya 1, dijelaskan pada gambar berikut ini.
A69: Tahun | B69: 2010 | C69: =B69+1 -> 2011 | D69: =C69+1 -> 2012 | E69: =D69+1 -> 2013 | F69: =E69+1 -> 2014 | G69: =F69+1 -> 2015 | H69: =G69+1 -> 2016 | I69: =H69+1 -> 2017 | J69: =I69+1 -> 2018
A70: Jumlah Klaim* | B70: =SUM(Calculate!C10:C11) -> 19 | C70: =SUM(Calculate!D10:D11) -> 15 | D70: =SUM(Calculate!E10:E11) -> 7 | E70: =SUM(Calculate!F10:F11) -> 28 | F70: =SUM(Calculate!G10:G11) -> 26 | G70: =SUM(Calculate!H10:H11) -> 30 | H70: =SUM(Calculate!I10:I11) -> 22 | I70: =SUM(Calculate!J10:J11) -> 31 | J70: =SUM(Calculate!K10:K11) -> 7
A71: *dalam unit | B71: **Jumlah Outstanding | D71: =Calculate!S11 -> 8 | E71: Klaim | F71: **Jumlah Settled | H71: =Calculate!S10 -> 177 | I71: Klaim
D72: =D71/(D71+H71) -> 0.043243243 | H72: =H71/(D71+H71) -> 0.95675676
A73: Gambar 6.1 Jumlah Klaim Berdasarkan Tahun Register dan Kondisi Klaim
A75: Dari data pada gambar 6.1 rincian jenis polis dan otority penanganan klaim dijelaskan pada gambar berikut ini.
A93: Tahun | B93: 2010 | C93: =B93+1 -> 2011 | D93: =C93+1 -> 2012 | E93: =D93+1 -> 2013 | F93: =E93+1 -> 2014 | G93: =F93+1 -> 2015 | H93: =G93+1 -> 2016 | I93: =H93+1 -> 2017 | J93: =I93+1 -> 2018
A94: Polis ACA * | B94: =Calculate!BM3 -> 19 | C94: =Calculate!BM4 -> 15 | D94: =Calculate!BM5 -> 7 | E94: =Calculate!BM6 -> 28 | F94: =Calculate!BM7 -> 20 | G94: =Calculate!BM8 -> 21 | H94: =Calculate!BM9 -> 16 | I94: =Calculate!BM10 -> 31 | J94: =Calculate!BM11 -> 5
B95: =IFERROR(B94/(B94+B96),0) -> 1 | C95: =IFERROR(C94/(C94+C96),0) -> 1 | D95: =IFERROR(D94/(D94+D96),0) -> 1 | E95: =IFERROR(E94/(E94+E96),0) -> 1 | F95: =IFERROR(F94/(F94+F96),0) -> 0.76923077 | G95: =IFERROR(G94/(G94+G96),0) -> 0.7 | H95: =IFERROR(H94/(H94+H96),0) -> 0.72727273 | I95: =IFERROR(I94/(I94+I96),0) -> 1 | J95: =IFERROR(J94/(J94+J96),0) -> 0.71428571
A96: Polis Inward* | B96: =Calculate!BN3 -> 0 | C96: =Calculate!BN4 -> 0 | D96: =Calculate!BN5 -> 0 | E96: =Calculate!BN6 -> 0 | F96: =Calculate!BN7 -> 6 | G96: =Calculate!BN8 -> 9 | H96: =Calculate!BN9 -> 6 | I96: =Calculate!BN10 -> 0 | J96: =Calculate!BN11 -> 2
B97: =IFERROR(B96/(B94+B96),0) -> 0 | C97: =IFERROR(C96/(C94+C96),0) -> 0 | D97: =IFERROR(D96/(D94+D96),0) -> 0 | E97: =IFERROR(E96/(E94+E96),0) -> 0 | F97: =IFERROR(F96/(F94+F96),0) -> 0.23076923 | G97: =IFERROR(G96/(G94+G96),0) -> 0.3 | H97: =IFERROR(H96/(H94+H96),0) -> 0.27272727 | I97: =IFERROR(I96/(I94+I96),0) -> 0 | J97: =IFERROR(J96/(J94+J96),0) -> 0.28571429
A98: *jumlah polis dalam unit
A99: Gambar 6.2 Jumlah Klaim Berdasarkan Tahun Register, Jenis Polis, dan Otority
A100: 6.2. Perbandingan Jumlah Klaim Berdasarkan Date of Loss dan Jumlah Settled pada Tahun 2016, 2017, dan 2018
A102: Jumlah kejadian dengan kategori klaim Casualty yang masuk pada PT. Asuransi Central Asia cabang Surabaya 1 bervariasi setiap bulan, berikut ini gambar grafik jumlah klaim berdasarkan waktu kejadian.
A122: Gambar 6.3 Perbandingan Jumlah Klaim Berdasarkan Date of Loss pada Tahun 2016, 2017, dan 2018 setiap Bulan dan Akumulasi
A125: Salah satu pengukuran kinerja dari divisi klaim adalah jumlah klaim yang berhail diselesaikan (settled), gambar 6.4 merupakan perbandingan jumlah klaim Casualty dengan status settled dalam bulan berjalan dari tahun sebelumnya pada divisi klaim non kendaraan bermotor PT. Asuransi Central Asia cabang Surabaya 1.
A146: Gambar 6.4 Perbandingan Komulatif Klaim Sudah Dilakukan Settled Klaim pada Tahun 2016, 2017, dan 2018 Setiap Bulan
A150: 6.3. Klaim dalam Pantauan
A151: Adapun jumlah klaim Casualty dalam pantauan dari tahun 2010 hingga 2018 di PT.Asuransi Central Asia cabang Surabaya 1, dijelaskan pada gambar berikut ini.
A168: Tahun | B168: 2010 | C168: =B168+1 -> 2011 | D168: =C168+1 -> 2012 | E168: =D168+1 -> 2013 | F168: =E168+1 -> 2014 | G168: =F168+1 -> 2015 | H168: =G168+1 -> 2016 | I168: =H168+1 -> 2017 | J168: =I168+1 -> 2018
A169: Jumlah Klaim*,** | B169: =Calculate!C71 -> 0 | C169: =Calculate!D71 -> 0 | D169: =Calculate!E71 -> 0 | E169: =Calculate!F71 -> 0 | F169: =Calculate!G71 -> 0 | G169: =Calculate!H71 -> 0 | H169: =Calculate!I71 -> 2 | I169: =Calculate!J71 -> 1 | J169: =Calculate!K71 -> 3
A170: *dalam unit | B170: **Total | D170: =SUM(Calculate!C71:R71) -> 6 | E170: Klaim
A171: Gambar 6.5. Jumlah Klaim yang Dipantau Berdasarkan Tahun Register
A173: Dalam proses memantau klaim Casualty di PT. Asuransi Central Asia cabang Surabaya 1 dibagi menjadi 4 (empat) kategori berdasarkan lama update klaim yaitu kurang dari sampai 7 hari, antara 7 sampai 14 hari, antara 14 sampai 30 hari, dan lebih dari 30 hari, adapun rincian tersebut dijelaskan pada gambar 6.6.
A194: Tahun | B194: 2010 | C194: =B194+1 -> 2011 | D194: =C194+1 -> 2012 | E194: =D194+1 -> 2013 | F194: =E194+1 -> 2014 | G194: =F194+1 -> 2015 | H194: =G194+1 -> 2016 | I194: =H194+1 -> 2017 | J194: =I194+1 -> 2018
A195: Lama Update > 30 hari* | B195: =Calculate!C90 -> 0 | C195: =Calculate!D90 -> 0 | D195: =Calculate!E90 -> 0 | E195: =Calculate!F90 -> 0 | F195: =Calculate!G90 -> 0 | G195: =Calculate!H90 -> 0 | H195: =Calculate!I90 -> 1 | I195: =Calculate!J90 -> 0 | J195: =Calculate!K90 -> 0
A197: *Jumlah Klaim dalam unit
A198: Gambar 6.6. Jumlah Klaim yang Dipantau Berdasarkan Tahun Register
A200: Dari data gambar 6.6 secara akumalasi berdasarkan kategori, dijelaskan pada gambar berikut ini.
A218: Gambar 6.7. Jumlah Klaim yang Dipantau Berdasarkan Lama Waktu Update

Sheet Casualty1
A1: Dari gambar 6.7 terdapat beberapa klaim bermasalah. adapun data klaim dan kendala dijabarkan pada tabel 6.1. berikut ini.
A3: Tabel 6.1. Data Klaim Casualty yang Bermasalah
A4: No. | B4: No. Klaim | C4: Nama Tertanggung | D4: Alasan | E4: Tanggal Update | F4: Status Update | G4: Solusi ditawarkan
A5: 1 | B5: 29.31.16.490017 | C5: Kezia Celine Wibowo | D5: TTG kuliah di Prancis. insturksi KACAB menunggu kuwitansi asli
A6: 2 | B6: 29.31.17.130016 | C6: Sinar Galaxy | D6: Tertanggung belum memberikan dokumen klaim | E6: 16.10.17 | F6: pak surya instruksi tidak boleh reminder 16.10.17 reminder mohon informasi ke Ibu Cintya TTG 05.06.17 info dari TTG. menunggu info dari TTG klaim ini jadi atau tidak
A7: 3 | B7: 29.31.17.490027 | C7: Nurul Aini Ongkowidjoyo | D7: Tertanggung tidak memberikan tanggapan atas permintaan dokumen | E7: 16,07,18 | F7: reminder 11 29,11,17 kirim permintaan dokumen ke TTG

Sheet Engineering
A1: Engineering
A50: 7.1. Klaim Settled dan Outstanding
A51: Adapun perbandingan klaim Engineering dengan status settled dan outstanding di PT.Asuransi Central Asia cabang Surabaya 1, dijelaskan pada gambar berikut ini.
A69: Tahun | B69: 2010 | C69: =B69+1 -> 2011 | D69: =C69+1 -> 2012 | E69: =D69+1 -> 2013 | F69: =E69+1 -> 2014 | G69: =F69+1 -> 2015 | H69: =G69+1 -> 2016 | I69: =H69+1 -> 2017 | J69: =I69+1 -> 2018
A70: Jumlah Klaim* | B70: =SUM(Calculate!C12:C13) -> 2 | C70: =SUM(Calculate!D12:D13) -> 9 | D70: =SUM(Calculate!E12:E13) -> 6 | E70: =SUM(Calculate!F12:F13) -> 16 | F70: =SUM(Calculate!G12:G13) -> 7 | G70: =SUM(Calculate!H12:H13) -> 36 | H70: =SUM(Calculate!I12:I13) -> 41 | I70: =SUM(Calculate!J12:J13) -> 25 | J70: =SUM(Calculate!K12:K13) -> 8
A71: *dalam unit | B71: **Jumlah Outstanding | D71: =Calculate!S13 -> 46 | E71: Klaim | F71: **Jumlah Settled | H71: =Calculate!S12 -> 104 | I71: Klaim
D72: =D71/(D71+H71) -> 0.30666667 | H72: =H71/(D71+H71) -> 0.69333333
A73: Gambar 7.1 Jumlah Klaim Berdasarkan Tahun Register dan Kondisi Klaim
A75: Dari data pada gambar 7.1 rincian jenis polis dan otority penanganan klaim dijelaskan pada gambar berikut ini.
A93: Tahun | B93: 2010 | C93: =B93+1 -> 2011 | D93: =C93+1 -> 2012 | E93: =D93+1 -> 2013 | F93: =E93+1 -> 2014 | G93: =F93+1 -> 2015 | H93: =G93+1 -> 2016 | I93: =H93+1 -> 2017 | J93: =I93+1 -> 2018
A94: Polis ACA * | B94: =Calculate!BV3 -> 2 | C94: =Calculate!BV4 -> 0 | D94: =Calculate!BV5 -> 0 | E94: =Calculate!BV6 -> 0 | F94: =Calculate!BV7 -> 2 | G94: =Calculate!BV8 -> 3 | H94: =Calculate!BV9 -> 2 | I94: =Calculate!BV10 -> 12 | J94: =Calculate!BV11 -> 0
B95: =IFERROR(B94/(B94+B96),0) -> 1 | C95: =IFERROR(C94/(C94+C96),0) -> 0 | D95: =IFERROR(D94/(D94+D96),0) -> 0 | E95: =IFERROR(E94/(E94+E96),0) -> 0 | F95: =IFERROR(F94/(F94+F96),0) -> 0.28571429 | G95: =IFERROR(G94/(G94+G96),0) -> 0.083333333 | H95: =IFERROR(H94/(H94+H96),0) -> 0.048780488 | I95: =IFERROR(I94/(I94+I96),0) -> 0.48 | J95: =IFERROR(J94/(J94+J96),0) -> 0
A96: Polis Inward* | B96: =Calculate!BW3 -> 0 | C96: =Calculate!BW4 -> 9 | D96: =Calculate!BW5 -> 6 | E96: =Calculate!BW6 -> 16 | F96: =Calculate!BW7 -> 5 | G96: =Calculate!BW8 -> 33 | H96: =Calculate!BW9 -> 39 | I96: =Calculate!BW10 -> 13 | J96: =Calculate!BW11 -> 8
B97: =IFERROR(B96/(B94+B96),0) -> 0 | C97: =IFERROR(C96/(C94+C96),0) -> 1 | D97: =IFERROR(D96/(D94+D96),0) -> 1 | E97: =IFERROR(E96/(E94+E96),0) -> 1 | F97: =IFERROR(F96/(F94+F96),0) -> 0.71428571 | G97: =IFERROR(G96/(G94+G96),0) -> 0.91666667 | H97: =IFERROR(H96/(H94+H96),0) -> 0.95121951 | I97: =IFERROR(I96/(I94+I96),0) -> 0.52 | J97: =IFERROR(J96/(J94+J96),0) -> 1
A98: *jumlah polis dalam unit
A99: Gambar 7.2 Jumlah Klaim Berdasarkan Tahun Register, Jenis Polis, dan Otority
A100: 7.2. Perbandingan Jumlah Klaim Berdasarkan Date of Loss dan Jumlah Settled pada Tahun 2016, 2017, dan 2018
A102: Jumlah kejadian dengan kategori klaim Engineering yang masuk pada PT. Asuransi Central Asia cabang Surabaya 1 bervariasi setiap bulan, berikut ini gambar grafik jumlah klaim berdasarkan waktu kejadian.
A122: Gambar 7.3 Perbandingan Jumlah Klaim Berdasarkan Date of Loss pada Tahun 2016, 2017, dan 2018 setiap Bulan dan Akumulasi
A125: Salah satu pengukuran kinerja dari divisi klaim adalah jumlah klaim yang berhail diselesaikan (settled), gambar 7.4 merupakan perbandingan jumlah klaim Engineering dengan status settled dalam bulan berjalan dari tahun sebelumnya pada divisi klaim non kendaraan bermotor PT. Asuransi Central Asia cabang Surabaya 1.
A146: Gambar 7.4 Perbandingan Komulatif Klaim Sudah Dilakukan Settled Klaim pada Tahun 2016, 2017, dan 2018 Setiap Bulan
A150: 7.3. Klaim dalam Pantauan
A151: Adapun jumlah klaim Engineering dalam pantauan dari tahun 2010 hingga 2018 di PT. Asuransi Central Asia cabang Surabaya 1, dijelaskan pada gambar berikut ini.
A168: Tahun | B168: 2010 | C168: =B168+1 -> 2011 | D168: =C168+1 -> 2012 | E168: =D168+1 -> 2013 | F168: =E168+1 -> 2014 | G168: =F168+1 -> 2015 | H168: =G168+1 -> 2016 | I168: =H168+1 -> 2017 | J168: =I168+1 -> 2018
A169: Jumlah Klaim*,** | B169: =Calculate!C72 -> 0 | C169: =Calculate!D72 -> 2 | D169: =Calculate!E72 -> 1 | E169: =Calculate!F72 -> 3 | F169: =Calculate!G72 -> 0 | G169: =Calculate!H72 -> 13 | H169: =Calculate!I72 -> 11 | I169: =Calculate!J72 -> 17 | J169: =Calculate!K72 -> 6
A170: *dalam unit | B170: **Total | D170: =SUM(Calculate!C72:R72) -> 53 | E170: Klaim
A171: Gambar 7.5. Jumlah Klaim yang Dipantau Berdasarkan Tahun Register
A173: Dalam proses memantau klaim Engineering di PT. Asuransi Central Asia cabang Surabaya 1 dibagi menjadi 4 (empat) kategori berdasarkan lama update klaim yaitu kurang dari sampai 7 hari, antara 7 sampai 14 hari, antara 14 sampai 30 hari, dan lebih dari 30 hari, adapun rincian tersebut dijelaskan pada gambar 7.6.
A194: Tahun | B194: 2010 | C194: =B194+1 -> 2011 | D194: =C194+1 -> 2012 | E194: =D194+1 -> 2013 | F194: =E194+1 -> 2014 | G194: =F194+1 -> 2015 | H194: =G194+1 -> 2016 | I194: =H194+1 -> 2017 | J194: =I194+1 -> 2018
A195: Lama Update > 30 hari* | B195: =Calculate!C91 -> 0 | C195: =Calculate!D91 -> 0 | D195: =Calculate!E91 -> 0 | E195: =Calculate!F91 -> 0 | F195: =Calculate!G91 -> 0 | G195: =Calculate!H91 -> 0 | H195: =Calculate!I91 -> 0 | I195: =Calculate!J91 -> 1 | J195: =Calculate!K91 -> 1
A197: *Jumlah Klaim dalam unit
A198: Gambar 7.6. Jumlah Klaim yang Dipantau Berdasarkan Tahun Register
A200: Dari data gambar 7.6 secara akumalasi berdasarkan kategori, dijelaskan pada gambar berikut ini.
A218: Gambar 7.7. Jumlah Klaim yang Dipantau Berdasarkan Lama Waktu Update

Sheet Engineering1
A1: Dari gambar 7.7 terdapat beberapa klaim bermasalah. adapun data klaim dan kendala dijabarkan pada tabel 7.1. berikut ini.
A3: Tabel 7.1. Data Klaim Engineeringyang Bermasalah
A4: No. | B4: No. Klaim | C4: Nama Tertanggung | D4: Alasan | E4: Tanggal Update | F4: Status Update | G4: Solusi ditawarkan
A5: 1 | B5: 02.31.17.050022 | C5: Pelabuhan Indonesia III (persero) | D5: DOL diluar periode. yang menurut leader sudah di Hold 1 bulan | E5: 27,02,18 | F5: reminder Ibu Inge 07,05,18 Bpk edo minta konfirmasi ke IbU Inge 26,03,18 buat surat penolakan ke KACAB 27,02,18 klaim ditolak HO 20,02,18 menunggu copy polis dari JASINDO 11,01,18 Bpk Hendra reminder 2 Ibu Inge 30,11,17 ibu Fatma reminder ibu Inge 22,11,17 info ibu inge akan minta wording ddl ke JASINDO 21,11,17 reminder 5 minta penjelasan Ibu Inge, perihal dol diluar periode, yang menurut leader sudah di Hold 1 bulan JASINDO 21.11.17 reminder 5 minta penjelasan Ibu Inge. perihal dol diluar periode. yang menurut leader sudah di Hold 1 bulan
A6: 2 | B6: 02.31.18.090005 | C6: Angkasa Pura 1 | D6: Klaim ditolak HO, karena terlambat lapor dari pihak leader. | E6: 23,03,18 | F6: buat penolakan ke KACAB

Sheet Ending
A1: - Terimakasih -
A23: Personil Divisi Klaim Non Kendaraan Bermotor
B25: Kepala Divisi : | D25: Hendro Tri Susanto
B26: Staff : | D26: Ahmad Subari

Sheet Calculate
A1: Jumlah Klaim | C1: 2010 | D1: =C1+1 -> 2011 | E1: =D1+1 -> 2012 | F1: =E1+1 -> 2013 | G1: =F1+1 -> 2014 | H1: =G1+1 -> 2015 | I1: =H1+1 -> 2016 | J1: =I1+1 -> 2017 | K1: =J1+1 -> 2018 | ... R1: =Q1+1 -> 2025 | S1: Sub jumlah | T1: Jumlah | U1: Otstanding | X1: Fire | AG1: cargo | AP1: hull | AY1: CPM | BH1: casualty | BQ1: engineering
A2: Fire | B2: Settled | C2: =[1]Information!$V$9 -> 135 | D2: =[1]Information!$V$10 -> 80 | E2: =[1]Information!$V$11 -> 101 | F2: =[1]Information!$V$12 -> 115 | G2: =[1]Information!$V$13 -> 105 | H2: =[1]Information!$V$14 -> 99 | I2: =[1]Information!$V$15 -> 151 | J2: =[1]Information!$V$16 -> 102 | K2: =[1]Information!$V$17 -> 4 | L2: =[1]Information!$V$18 -> 0 | M2: =[1]Information!$V$19 -> 0 | N2: =[1]Information!$V$20 -> 0 | O2: =[1]Information!$V$21 -> 0 | P2: =[1]Information!$V$22 -> 0 | Q2: =[1]Information!$V$23 -> 0 | R2: =[1]Information!$V$24 -> 0 | S2: =SUM(C2:R2) -> 892 | T2: =SUM(S2:S3) -> 985 | U2: =S3 -> 93 | X2: Polis ACA | Z2: Polis Inward | AC2: Polis ACA | AD2: Polis Inward | AG2: Polis ACA | AI2: Polis Inward | AL2: Polis ACA | AM2: Polis Inward | AP2: Polis ACA | AR2: Polis Inward | AU2: Polis ACA | AV2: Polis Inward | AY2: Polis ACA | BA2: Polis Inward | BD2: Polis ACA | BE2: Polis Inward | BH2: Polis ACA | BJ2: Polis Inward | BM2: Polis ACA | BN2: Polis Inward | BQ2: Polis ACA | BS2: Polis Inward | BV2: Polis ACA | BW2: Polis Inward
B3: Outstanding | C3: =[1]Information!$W$9 -> 1 | D3: =[1]Information!$W$10 -> 0 | E3: =[1]Information!$W$11 -> 6 | F3: =[1]Information!$W$12 -> 3 | G3: =[1]Information!$W$13 -> 2 | H3: =[1]Information!$W$14 -> 1 | I3: =[1]Information!$W$15 -> 17 | J3: =[1]Information!$W$16 -> 32 | K3: =[1]Information!$W$17 -> 31 | L3: =[1]Information!$W$18 -> 0 | M3: =[1]Information!$W$19 -> 0 | N3: =[1]Information!$W$20 -> 0 | O3: =[1]Information!$W$21 -> 0 | P3: =[1]Information!$W$22 -> 0 | Q3: =[1]Information!$W$23 -> 0 | R3: =[1]Information!$W$24 -> 0 | S3: =SUM(C3:R3) -> 93 | W3: =[1]Information!X9 -> 2010 | X3: =[1]Information!Y9 -> 43 | Y3: =[1]Information!Z9 -> 46 | Z3: =[1]Information!AA9 -> 26 | AA3: =[1]Information!AB9 -> 21 | AC3: =SUM(X3:Y3) -> 89 | AD3: =SUM(Z3:AA3) -> 47 | AF3: =[2]Information!X9 -> 2010 | AG3: =[2]Information!Y9 -> 6 | AH3: =[2]Information!Z9 -> 8 | AI3: =[2]Information!AA9 -> 8 | AJ3: =[2]Information!AB9 -> 11 | AL3: =SUM(AG3:AH3) -> 14 | AM3: =SUM(AI3:AJ3) -> 19 | AO3: =[4]Information!X9 -> 2010 | AP3: =[4]Information!Y9 -> 0 | AQ3: =[4]Information!Z9 -> 3 | AR3: =[4]Information!AA9 -> 0 | AS3: =[4]Information!AB9 -> 2 | AU3: =SUM(AP3:AQ3) -> 3 | AV3: =SUM(AR3:AS3) -> 2 | AX3: =[5]Information!X9 -> 2010 | AY3: =[3]Information!Y9 -> 0 | AZ3: =[3]Information!Z9 -> 0 | BA3: =[3]Information!AA9 -> 0 | BB3: =[3]Information!AB9 -> 0 | BD3: =SUM(AY3:AZ3) -> 0 | BE3: =SUM(BA3:BB3) -> 0 | BG3: =[3]Information!X9 -> 2010 | BH3: =[5]Information!Y9 -> 17 | BI3: =[5]Information!Z9 -> 2 | BJ3: =[5]Information!AA9 -> 0 | BK3: =[5]Information!AB9 -> 0 | BM3: =SUM(BH3:BI3) -> 19 | BN3: =SUM(BJ3:BK3) -> 0 | BP3: =[6]Information!X9 -> 2010 | BQ3: =[6]Information!Y9 -> 0 | BR3: =[6]Information!Z9 -> 2 | BS3: =[6]Information!AA9 -> 0 | BT3: =[6]Information!AB9 -> 0 | BV3: =SUM(BQ3:BR3) -> 2 | BW3: =SUM(BS3:BT3) -> 0
A4: Cargo | B4: Settled | C4: =[2]Information!$V$9 -> 33 | D4: =[2]Information!$V$10 -> 28 | E4: =[2]Information!$V$11 -> 32 | F4: =[2]Information!$V$12 -> 51 | G4: =[2]Information!$V$13 -> 48 | H4: =[2]Information!$V$14 -> 35 | I4: =[2]Information!$V$15 -> 32 | J4: =[2]Information!$V$16 -> 17 | K4: =[2]Information!$V$17 -> 2 | L4: =[2]Information!$V$18 -> 0 | M4: =[2]Information!$V$19 -> 0 | N4: =[2]Information!$V$20 -> 0 | O4: =[2]Information!$V$21 -> 0 | P4: =[2]Information!$V$22 -> 0 | Q4: =[2]Information!$V$23 -> 0 | R4: =[2]Information!$V$24 -> 0 | S4: =SUM(C4:R4) -> 278 | T4: =SUM(S4:S5) -> 305 | U4: =S5 -> 27 | W4: =W3+1 -> 2011 | X4: =[1]Information!Y10 -> 35 | Y4: =[1]Information!Z10 -> 24 | Z4: =[1]Information!AA10 -> 14 | AA4: =[1]Information!AB10 -> 7 | AC4: =SUM(X4:Y4) -> 59 | AD4: =SUM(Z4:AA4) -> 21 | AF4: =AF3+1 -> 2011 | AG4: =[2]Information!Y10 -> 10 | AH4: =[2]Information!Z10 -> 9 | AI4: =[2]Information!AA10 -> 2 | AJ4: =[2]Information!AB10 -> 12 | AL4: =SUM(AG4:AH4) -> 19 | AM4: =SUM(AI4:AJ4) -> 14 | AO4: =AO3+1 -> 2011 | AP4: =[4]Information!Y10 -> 0 | AQ4: =[4]Information!Z10 -> 3 | AR4: =[4]Information!AA10 -> 0 | AS4: =[4]Information!AB10 -> 5 | AU4: =SUM(AP4:AQ4) -> 3 | AV4: =SUM(AR4:AS4) -> 5 | AX4: =AX3+1 -> 2011 | AY4: =[3]Information!Y10 -> 0 | AZ4: =[3]Information!Z10 -> 0 | BA4: =[3]Information!AA10 -> 0 | BB4: =[3]Information!AB10 -> 0 | BD4: =SUM(AY4:AZ4) -> 0 | BE4: =SUM(BA4:BB4) -> 0 | BG4: =BG3+1 -> 2011 | BH4: =[5]Information!Y10 -> 7 | BI4: =[5]Information!Z10 -> 8 | BJ4: =[5]Information!AA10 -> 0 | BK4: =[5]Information!AB10 -> 0 | BM4: =SUM(BH4:BI4) -> 15 | BN4: =SUM(BJ4:BK4) -> 0 | BP4: =BP3+1 -> 2011 | BQ4: =[6]Information!Y10 -> 0 | BR4: =[6]Information!Z10 -> 0 | BS4: =[6]Information!AA10 -> 0 | BT4: =[6]Information!AB10 -> 9 | BV4: =SUM(BQ4:BR4) -> 0 | BW4: =SUM(BS4:BT4) -> 9
B5: Outstanding | C5: =[2]Information!$W$9 -> 0 | D5: =[2]Information!$W$10 -> 5 | E5: =[2]Information!$W$11 -> 4 | F5: =[2]Information!$W$12 -> 1 | G5: =[2]Information!$W$13 -> 0 | H5: =[2]Information!$W$14 -> 0 | I5: =[2]Information!$W$15 -> 5 | J5: =[2]Information!$W$16 -> 3 | K5: =[2]Information!$W$17 -> 9 | L5: =[2]Information!$W$18 -> 0 | M5: =[2]Information!$W$19 -> 0 | N5: =[2]Information!$W$20 -> 0 | O5: =[2]Information!$W$21 -> 0 | P5: =[2]Information!$W$22 -> 0 | Q5: =[2]Information!$W$23 -> 0 | R5: =[2]Information!$W$24 -> 0 | S5: =SUM(C5:R5) -> 27 | W5: =W4+1 -> 2012 | X5: =[1]Information!Y11 -> 37 | Y5: =[1]Information!Z11 -> 23 | Z5: =[1]Information!AA11 -> 29 | AA5: =[1]Information!AB11 -> 18 | AC5: =SUM(X5:Y5) -> 60 | AD5: =SUM(Z5:AA5) -> 47 | AF5: =AF4+1 -> 2012 | AG5: =[2]Information!Y11 -> 16 | AH5: =[2]Information!Z11 -> 11 | AI5: =[2]Information!AA11 -> 6 | AJ5: =[2]Information!AB11 -> 3 | AL5: =SUM(AG5:AH5) -> 27 | AM5: =SUM(AI5:AJ5) -> 9 | AO5: =AO4+1 -> 2012 | AP5: =[4]Information!Y11 -> 0 | AQ5: =[4]Information!Z11 -> 3 | AR5: =[4]Information!AA11 -> 0 | AS5: =[4]Information!AB11 -> 4 | AU5: =SUM(AP5:AQ5) -> 3 | AV5: =SUM(AR5:AS5) -> 4 | AX5: =AX4+1 -> 2012 | AY5: =[3]Information!Y11 -> 0 | AZ5: =[3]Information!Z11 -> 0 | BA5: =[3]Information!AA11 -> 0 | BB5: =[3]Information!AB11 -> 0 | BD5: =SUM(AY5:AZ5) -> 0 | BE5: =SUM(BA5:BB5) -> 0 | BG5: =BG4+1 -> 2012 | BH5: =[5]Information!Y11 -> 6 | BI5: =[5]Information!Z11 -> 1 | BJ5: =[5]Information!AA11 -> 0 | BK5: =[5]Information!AB11 -> 0 | BM5: =SUM(BH5:BI5) -> 7 | BN5: =SUM(BJ5:BK5) -> 0 | BP5: =BP4+1 -> 2012 | BQ5: =[6]Information!Y11 -> 0 | BR5: =[6]Information!Z11 -> 0 | BS5: =[6]Information!AA11 -> 0 | BT5: =[6]Information!AB11 -> 6 | BV5: =SUM(BQ5:BR5) -> 0 | BW5: =SUM(BS5:BT5) -> 6
A6: Hull | B6: Settled | C6: =[4]Information!$V$9 -> 4 | D6: =[4]Information!$V$10 -> 6 | E6: =[4]Information!$V$11 -> 6 | F6: =[4]Information!$V$12 -> 1 | G6: =[4]Information!$V$13 -> 0 | H6: =[4]Information!$V$14 -> 0 | I6: =[4]Information!$V$15 -> 2 | J6: =[4]Information!$V$16 -> 2 | K6: =[4]Information!$V$17 -> 0 | L6: =[4]Information!$V$18 -> 0 | M6: =[4]Information!$V$19 -> 0 | N6: =[4]Information!$V$20 -> 0 | O6: =[4]Information!$V$21 -> 0 | P6: =[4]Information!$V$22 -> 0 | Q6: =[4]Information!$V$23 -> 0 | R6: =[4]Information!$V$24 -> 0 | S6: =SUM(C6:R6) -> 21 | T6: =SUM(S6:S7) -> 27 | U6: =S7 -> 6 | W6: =W5+1 -> 2013 | X6: =[1]Information!Y12 -> 38 | Y6: =[1]Information!Z12 -> 36 | Z6: =[1]Information!AA12 -> 29 | AA6: =[1]Information!AB12 -> 15 | AC6: =SUM(X6:Y6) -> 74 | AD6: =SUM(Z6:AA6) -> 44 | AF6: =AF5+1 -> 2013 | AG6: =[2]Information!Y12 -> 14 | AH6: =[2]Information!Z12 -> 29 | AI6: =[2]Information!AA12 -> 2 | AJ6: =[2]Information!AB12 -> 7 | AL6: =SUM(AG6:AH6) -> 43 | AM6: =SUM(AI6:AJ6) -> 9 | AO6: =AO5+1 -> 2013 | AP6: =[4]Information!Y12 -> 0 | AQ6: =[4]Information!Z12 -> 1 | AR6: =[4]Information!AA12 -> 0 | AS6: =[4]Information!AB12 -> 0 | AU6: =SUM(AP6:AQ6) -> 1 | AV6: =SUM(AR6:AS6) -> 0 | AX6: =AX5+1 -> 2013 | AY6: =[3]Information!Y12 -> 0 | AZ6: =[3]Information!Z12 -> 0 | BA6: =[3]Information!AA12 -> 0 | BB6: =[3]Information!AB12 -> 0 | BD6: =SUM(AY6:AZ6) -> 0 | BE6: =SUM(BA6:BB6) -> 0 | BG6: =BG5+1 -> 2013 | BH6: =[5]Information!Y12 -> 24 | BI6: =[5]Information!Z12 -> 4 | BJ6: =[5]Information!AA12 -> 0 | BK6: =[5]Information!AB12 -> 0 | BM6: =SUM(BH6:BI6) -> 28 | BN6: =SUM(BJ6:BK6) -> 0 | BP6: =BP5+1 -> 2013 | BQ6: =[6]Information!Y12 -> 0 | BR6: =[6]Information!Z12 -> 0 | BS6: =[6]Information!AA12 -> 0 | BT6: =[6]Information!AB12 -> 16 | BV6: =SUM(BQ6:BR6) -> 0 | BW6: =SUM(BS6:BT6) -> 16
B7: Outstanding | C7: =[4]Information!$W$9 -> 1 | D7: =[4]Information!$W$10 -> 2 | E7: =[4]Information!$W$11 -> 1 | F7: =[4]Information!$W$12 -> 0 | G7: =[4]Information!$W$13 -> 0 | H7: =[4]Information!$W$14 -> 0 | I7: =[4]Information!$W$15 -> 0 | J7: =[4]Information!$W$16 -> 2 | K7: =[4]Information!$W$17 -> 0 | L7: =[4]Information!$W$18 -> 0 | M7: =[4]Information!$W$19 -> 0 | N7: =[4]Information!$W$20 -> 0 | O7: =[4]Information!$W$21 -> 0 | P7: =[4]Information!$W$22 -> 0 | Q7: =[4]Information!$W$23 -> 0 | R7: =[4]Information!$W$24 -> 0 | S7: =SUM(C7:R7) -> 6 | W7: =W6+1 -> 2014 | X7: =[1]Information!Y13 -> 23 | Y7: =[1]Information!Z13 -> 35 | Z7: =[1]Information!AA13 -> 21 | AA7: =[1]Information!AB13 -> 28 | AC7: =SUM(X7:Y7) -> 58 | AD7: =SUM(Z7:AA7) -> 49 | AF7: =AF6+1 -> 2014 | AG7: =[2]Information!Y13 -> 24 | AH7: =[2]Information!Z13 -> 23 | AI7: =[2]Information!AA13 -> 0 | AJ7: =[2]Information!AB13 -> 1 | AL7: =SUM(AG7:AH7) -> 47 | AM7: =SUM(AI7:AJ7) -> 1 | AO7: =AO6+1 -> 2014 | AP7: =[4]Information!Y13 -> 0 | AQ7: =[4]Information!Z13 -> 0 | AR7: =[4]Information!AA13 -> 0 | AS7: =[4]Information!AB13 -> 0 | AU7: =SUM(AP7:AQ7) -> 0 | AV7: =SUM(AR7:AS7) -> 0 | AX7: =AX6+1 -> 2014 | AY7: =[3]Information!Y13 -> 0 | AZ7: =[3]Information!Z13 -> 1 | BA7: =[3]Information!AA13 -> 0 | BB7: =[3]Information!AB13 -> 0 | BD7: =SUM(AY7:AZ7) -> 1 | BE7: =SUM(BA7:BB7) -> 0 | BG7: =BG6+1 -> 2014 | BH7: =[5]Information!Y13 -> 18 | BI7: =[5]Information!Z13 -> 2 | BJ7: =[5]Information!AA13 -> 6 | BK7: =[5]Information!AB13 -> 0 | BM7: =SUM(BH7:BI7) -> 20 | BN7: =SUM(BJ7:BK7) -> 6 | BP7: =BP6+1 -> 2014 | BQ7: =[6]Information!Y13 -> 0 | BR7: =[6]Information!Z13 -> 2 | BS7: =[6]Information!AA13 -> 0 | BT7: =[6]Information!AB13 -> 5 | BV7: =SUM(BQ7:BR7) -> 2 | BW7: =SUM(BS7:BT7) -> 5
A8: CPM | B8: Settled | C8: =[3]Information!$V$9 -> 0 | D8: =[3]Information!$V$10 -> 0 | E8: =[3]Information!$V$11 -> 0 | F8: =[3]Information!$V$12 -> 0 | G8: =[3]Information!$V$13 -> 1 | H8: =[3]Information!$V$14 -> 8 | I8: =[3]Information!$V$15 -> 19 | J8: =[3]Information!$V$16 -> 1 | K8: =[3]Information!$V$17 -> 0 | L8: =[3]Information!$V$18 -> 0 | M8: =[3]Information!$V$19 -> 0 | N8: =[3]Information!$V$20 -> 0 | O8: =[3]Information!$V$21 -> 0 | P8: =[3]Information!$V$22 -> 0 | Q8: =[3]Information!$V$23 -> 0 | R8: =[3]Information!$V$24 -> 0 | S8: =SUM(C8:R8) -> 29 | T8: =SUM(S8:S9) -> 94 | U8: =S9 -> 65 | W8: =W7+1 -> 2015 | X8: =[1]Information!Y14 -> 18 | Y8: =[1]Information!Z14 -> 24 | Z8: =[1]Information!AA14 -> 49 | AA8: =[1]Information!AB14 -> 9 | AC8: =SUM(X8:Y8) -> 42 | AD8: =SUM(Z8:AA8) -> 58 | AF8: =AF7+1 -> 2015 | AG8: =[2]Information!Y14 -> 17 | AH8: =[2]Information!Z14 -> 14 | AI8: =[2]Information!AA14 -> 1 | AJ8: =[2]Information!AB14 -> 3 | AL8: =SUM(AG8:AH8) -> 31 | AM8: =SUM(AI8:AJ8) -> 4 | AO8: =AO7+1 -> 2015 | AP8: =[4]Information!Y14 -> 0 | AQ8: =[4]Information!Z14 -> 0 | AR8: =[4]Information!AA14 -> 0 | AS8: =[4]Information!AB14 -> 0 | AU8: =SUM(AP8:AQ8) -> 0 | AV8: =SUM(AR8:AS8) -> 0 | AX8: =AX7+1 -> 2015 | AY8: =[3]Information!Y14 -> 0 | AZ8: =[3]Information!Z14 -> 4 | BA8: =[3]Information!AA14 -> 32 | BB8: =[3]Information!AB14 -> 2 | BD8: =SUM(AY8:AZ8) -> 4 | BE8: =SUM(BA8:BB8) -> 34 | BG8: =BG7+1 -> 2015 | BH8: =[5]Information!Y14 -> 15 | BI8: =[5]Information!Z14 -> 6 | BJ8: =[5]Information!AA14 -> 6 | BK8: =[5]Information!AB14 -> 3 | BM8: =SUM(BH8:BI8) -> 21 | BN8: =SUM(BJ8:BK8) -> 9 | BP8: =BP7+1 -> 2015 | BQ8: =[6]Information!Y14 -> 0 | BR8: =[6]Information!Z14 -> 3 | BS8: =[6]Information!AA14 -> 0 | BT8: =[6]Information!AB14 -> 33 | BV8: =SUM(BQ8:BR8) -> 3 | BW8: =SUM(BS8:BT8) -> 33
